<?xml version="1.0" ?>
<!-- This URDF was automatically created by SolidWorks to URDF Exporter! Originally created by Stephen Brawner (brawner@gmail.com) 
     Commit Version: 1.6.0-1-g15f4949  Build Version: 1.6.7594.29634
     For more information, please see http://wiki.ros.org/sw_urdf_exporter -->
<robot
  name="sparky" xmlns:xacro="http://www.ros.org/wiki/xacro">

  <xacro:macro name="box_inertia" params="m w h d">
        <inertial>
            <mass value="${m}"/>
            <inertia ixx="${m/12.0 * (d*d + h*h)}" ixy="0.0" ixz="0.0" iyy="${m/12.0 * (w*w + h*h)}" iyz="0.0" izz="${m/12.0 * (w*w + d*d)}"/>
        </inertial>
    </xacro:macro>

    <xacro:macro name="cylinder_inertia" params="m r h">
        <inertial>
            <mass value="${m}"/>
            <inertia ixx="${m*(3*r*r+h*h)/12}" ixy = "0" ixz = "0" iyy="${m*(3*r*r+h*h)/12}" iyz = "0" izz="${m*r*r/2}"/> 
        </inertial>
    </xacro:macro>

  <link
    name="base_link">
      <xacro:box_inertia m="10" w="0.4" h="0.35" d="0.4"/>
    <visual>
      <origin
        xyz="0 0 0"
        rpy="0 0 0" />
      <geometry>
        <mesh
          filename="package://sparky/meshes/base_link.STL" />
      </geometry>
      <material
        name="">
        <color
          rgba="0.792156862745098 0.819607843137255 0.933333333333333 1" />
      </material>
    </visual>
    <collision>
      <origin
        xyz="0 0 0"
        rpy="0 0 0" />
      <geometry>
        <mesh
          filename="package://sparky/meshes/base_link.STL" />
      </geometry>
    </collision>
  </link>
  <link
    name="front_left_link">
    <inertial>
      <origin
        xyz="-1.7808E-07 -8.8465E-12 0.00059368"
        rpy="0 0 0" />
      <mass
        value="0.085481" />
      <inertia
        ixx="3.4029E-05"
        ixy="-1.5665E-18"
        ixz="1.0513E-10"
        iyy="3.4029E-05"
        iyz="-3.9938E-13"
        izz="6.0831E-05" />
    </inertial>
    <visual>
      <origin
        xyz="0 0 0"
        rpy="0 0 0" />
      <geometry>
        <mesh
          filename="package://sparky/meshes/front_left_link.STL" />
      </geometry>
      <material
        name="">
        <color
          rgba="0.79216 0.81961 0.93333 1" />
      </material>
    </visual>
    <collision>
      <origin
        xyz="0 0 0"
        rpy="0 0 0" />
      <geometry>
        <mesh
          filename="package://sparky/meshes/front_left_link.STL" />
      </geometry>
    </collision>
  </link>
  <joint
    name="front_left_joint"
    type="continuous">
    <origin
      xyz="0.1615 -0.090901 0.058911"
      rpy="-1.5708 0 1.5708" />
    <parent
      link="base_link" />
    <child
      link="front_left_link" />
    <axis
      xyz="0 0 0" />
  </joint>
  <link
    name="back_left_link">
    <inertial>
      <origin
        xyz="-1.78075780260523E-07 -8.8465276770755E-12 0.000593680590457724"
        rpy="0 0 0" />
      <mass
        value="0.0854814877069659" />
      <inertia
        ixx="3.40289944202775E-05"
        ixy="-1.56654775802679E-18"
        ixz="1.05129255299102E-10"
        iyy="3.40290134452951E-05"
        iyz="-3.99375833188094E-13"
        izz="6.08306716950079E-05" />
    </inertial>
    <visual>
      <origin
        xyz="0 0 0"
        rpy="0 0 0" />
      <geometry>
        <mesh
          filename="package://sparky/meshes/back_left_link.STL" />
      </geometry>
      <material
        name="">
        <color
          rgba="0.792156862745098 0.819607843137255 0.933333333333333 1" />
      </material>
    </visual>
    <collision>
      <origin
        xyz="0 0 0"
        rpy="0 0 0" />
      <geometry>
        <mesh
          filename="package://sparky/meshes/back_left_link.STL" />
      </geometry>
    </collision>
  </link>
  <joint
    name="back_left_joint"
    type="continuous">
    <origin
      xyz="0.1615 0.064075 0.058911"
      rpy="-1.5708 0 1.5708" />
    <parent
      link="base_link" />
    <child
      link="back_left_link" />
    <axis
      xyz="0 0 0" />
  </joint>
  <link
    name="front_right_link">
    <inertial>
      <origin
        xyz="-1.7808E-07 0 -0.00059368"
        rpy="0 0 0" />
      <mass
        value="0.085481" />
      <inertia
        ixx="3.4029E-05"
        ixy="-4.5958E-24"
        ixz="-1.0513E-10"
        iyy="3.4029E-05"
        iyz="2.7084E-21"
        izz="6.0831E-05" />
    </inertial>
    <visual>
      <origin
        xyz="0 0 0"
        rpy="0 0 0" />
      <geometry>
        <mesh
          filename="package://sparky/meshes/front_right_link.STL" />
      </geometry>
      <material
        name="">
        <color
          rgba="0.79216 0.81961 0.93333 1" />
      </material>
    </visual>
    <collision>
      <origin
        xyz="0 0 0"
        rpy="0 0 0" />
      <geometry>
        <mesh
          filename="package://sparky/meshes/front_right_link.STL" />
      </geometry>
    </collision>
  </link>
  <joint
    name="front_right_joint"
    type="continuous">
    <origin
      xyz="-0.15893 -0.090901 0.058911"
      rpy="1.5708 0 -1.5708" />
    <parent
      link="base_link" />
    <child
      link="front_right_link" />
    <axis
      xyz="0 0 0" />
  </joint>
  <link
    name="back_right_link">
    <inertial>
      <origin
        xyz="-1.78075780288278E-07 0 -0.000593680590457724"
        rpy="0 0 0" />
      <mass
        value="0.0854814877069659" />
      <inertia
        ixx="3.40289944202775E-05"
        ixy="-4.59578242016804E-24"
        ixz="-1.05129255294325E-10"
        iyy="3.40290134452951E-05"
        iyz="2.70844437422832E-21"
        izz="6.08306716950079E-05" />
    </inertial>
    <visual>
      <origin
        xyz="0 0 0"
        rpy="0 0 0" />
      <geometry>
        <mesh
          filename="package://sparky/meshes/back_right_link.STL" />
      </geometry>
      <material
        name="">
        <color
          rgba="0.792156862745098 0.819607843137255 0.933333333333333 1" />
      </material>
    </visual>
    <collision>
      <origin
        xyz="0 0 0"
        rpy="0 0 0" />
      <geometry>
        <mesh
          filename="package://sparky/meshes/back_right_link.STL" />
      </geometry>
    </collision>
  </link>
  <joint
    name="back_right_joint"
    type="continuous">
    <origin
      xyz="-0.15893 0.064075 0.058911"
      rpy="1.5708 0 -1.5708" />
    <parent
      link="base_link" />
    <child
      link="back_right_link" />
    <axis
      xyz="0 0 0" />
  </joint>
  <link
    name="lidar_link">
    <inertial>
      <origin
        xyz="0 0 0"
        rpy="0 0 0" />
      <mass
        value="1" />
      <inertia
        ixx="0"
        ixy="0"
        ixz="0"
        iyy="0"
        iyz="0"
        izz="0" />
    </inertial>
    <visual>
      <origin
        xyz="0 0 0"
        rpy="0 0 0" />
      <geometry>
        <mesh
          filename="package://sparky/meshes/lidar_link.STL" />
      </geometry>
      <material
        name="">
        <color
          rgba="1 1 1 1" />
      </material>
    </visual>
    <collision>
      <origin
        xyz="0 0 0"
        rpy="0 0 0" />
      <geometry>
        <mesh
          filename="package://sparky/meshes/lidar_link.STL" />
      </geometry>
    </collision>
  </link>
  <joint
    name="lidar_joint"
    type="fixed">
    <origin
      xyz="0.00128408400018751 -0.199342393380161 0.141250111826523"
      rpy="-1.5707963267949 0 -1.5707963267949" />
    <parent
      link="base_link" />
    <child
      link="lidar_link" />
    <axis
      xyz="0 0 0" />
  </joint>
</robot>